{
    "cve": {
        "data_type": "CVE",
        "data_format": "MITRE",
        "data_version": "4.0",
        "CVE_data_meta": {
            "ID": "CVE-2025-2953",
            "ASSIGNER": "cna@vuldb.com"
        },
        "problemtype": {
            "problemtype_data": [
                {
                    "description": [
                        {
                            "lang": "en",
                            "value": "CWE-404"
                        }
                    ]
                }
            ]
        },
        "references": {
            "reference_data": [
                {
                    "url": "https:\/\/github.com\/pytorch\/pytorch\/issues\/149274",
                    "name": "https:\/\/github.com\/pytorch\/pytorch\/issues\/149274",
                    "refsource": "",
                    "tags": []
                },
                {
                    "url": "https:\/\/github.com\/pytorch\/pytorch\/issues\/149274#issue-2923122269",
                    "name": "https:\/\/github.com\/pytorch\/pytorch\/issues\/149274#issue-2923122269",
                    "refsource": "",
                    "tags": []
                },
                {
                    "url": "https:\/\/vuldb.com\/?ctiid.302006",
                    "name": "VDB-302006 | CTI Indicators (IOB, IOC, IOA)",
                    "refsource": "",
                    "tags": []
                },
                {
                    "url": "https:\/\/vuldb.com\/?id.302006",
                    "name": "VDB-302006 | PyTorch torch.mkldnn_max_pool2d denial of service",
                    "refsource": "",
                    "tags": []
                },
                {
                    "url": "https:\/\/vuldb.com\/?submit.521279",
                    "name": "Submit #521279 | pytorch PyTorch version: 2.6.0+cu124 Floating point exception",
                    "refsource": "",
                    "tags": []
                }
            ]
        },
        "description": {
            "description_data": [
                {
                    "lang": "en",
                    "value": "A vulnerability, which was classified as problematic, has been found in PyTorch 2.6.0+cu124. Affected by this issue is the function torch.mkldnn_max_pool2d. The manipulation leads to denial of service. An attack has to be approached locally. The exploit has been disclosed to the public and may be used."
                }
            ]
        }
    },
    "configurations": {
        "CVE_data_version": "4.0",
        "nodes": []
    },
    "impact": {
        "baseMetricV3": {
            "cvssV3": {
                "version": "3.1",
                "vectorString": "CVSS:3.1\/AV:L\/AC:L\/PR:L\/UI:N\/S:U\/C:N\/I:N\/A:L",
                "attackVector": "LOCAL",
                "attackComplexity": "LOW",
                "privilegesRequired": "LOW",
                "userInteraction": "NONE",
                "scope": "UNCHANGED",
                "confidentialityImpact": "NONE",
                "integrityImpact": "NONE",
                "availabilityImpact": "LOW",
                "baseScore": 3.3,
                "baseSeverity": "LOW"
            },
            "exploitabilityScore": 1.8,
            "impactScore": 1.4
        }
    },
    "publishedDate": "2025-03-30T16:15Z",
    "lastModifiedDate": "2025-03-30T16:15Z"
}